/usr/local/src/myproject/venv/lib/python2.6/site-packages/flask_sqlalchemy/__init__.py:839: FSADeprecationWarning: SQLALCHEMY_TRACK_MODIFICATIONS adds significant overhead and will be disabled by default in the future.  Set it to True or False to suppress this warning.
  'SQLALCHEMY_TRACK_MODIFICATIONS adds significant overhead and '
 * Running on http://0.0.0.0:5000/ (Press CTRL+C to quit)
 * Restarting with stat
/usr/local/src/myproject/venv/lib/python2.6/site-packages/flask_sqlalchemy/__init__.py:839: FSADeprecationWarning: SQLALCHEMY_TRACK_MODIFICATIONS adds significant overhead and will be disabled by default in the future.  Set it to True or False to suppress this warning.
  'SQLALCHEMY_TRACK_MODIFICATIONS adds significant overhead and '
 * Debugger is active!
 * Debugger pin code: 204-225-200
113.106.106.98 - - [25/Mar/2017 09:25:40] "GET / HTTP/1.1" 302 -
/usr/local/src/myproject/venv/lib/python2.6/site-packages/sqlalchemy/sql/compiler.py:624: SAWarning: Can't resolve label reference 'total DESC'; converting to text() (this warning may be suppressed after 10 occurrences)
  util.ellipses_string(element.element))
113.106.106.98 - - [25/Mar/2017 09:25:40] "GET /blog/ HTTP/1.1" 200 -
113.106.106.98 - - [25/Mar/2017 09:25:40] "GET /static/css/bootstrap.min.css HTTP/1.1" 304 -
113.106.106.98 - - [25/Mar/2017 09:25:40] "GET /static/jquery/jquery-1.11.2.min.js HTTP/1.1" 304 -
113.106.106.98 - - [25/Mar/2017 09:25:40] "GET /static/js/bootstrap.min.js HTTP/1.1" 304 -
113.106.106.98 - - [25/Mar/2017 09:27:09] "GET / HTTP/1.1" 302 -
113.106.106.98 - - [25/Mar/2017 09:27:09] "GET /blog/ HTTP/1.1" 200 -
205.252.237.59 - - [25/Mar/2017 09:28:08] "GET /blog/ HTTP/1.1" 200 -
205.252.237.59 - - [25/Mar/2017 09:28:13] "GET /register HTTP/1.1" 200 -
205.252.237.59 - - [25/Mar/2017 09:28:13] "GET /register HTTP/1.1" 200 -
205.252.237.59 - - [25/Mar/2017 09:29:37] "POST /register HTTP/1.1" 500 -
Traceback (most recent call last):
  File "/usr/local/src/myproject/venv/lib/python2.6/site-packages/flask/app.py", line 1836, in __call__
    return self.wsgi_app(environ, start_response)
  File "/usr/local/src/myproject/venv/lib/python2.6/site-packages/flask/app.py", line 1820, in wsgi_app
    response = self.make_response(self.handle_exception(e))
  File "/usr/local/src/myproject/venv/lib/python2.6/site-packages/flask/app.py", line 1403, in handle_exception
    reraise(exc_type, exc_value, tb)
  File "/usr/local/src/myproject/venv/lib/python2.6/site-packages/flask/app.py", line 1817, in wsgi_app
    response = self.full_dispatch_request()
  File "/usr/local/src/myproject/venv/lib/python2.6/site-packages/flask/app.py", line 1477, in full_dispatch_request
    rv = self.handle_user_exception(e)
  File "/usr/local/src/myproject/venv/lib/python2.6/site-packages/flask/app.py", line 1381, in handle_user_exception
    reraise(exc_type, exc_value, tb)
  File "/usr/local/src/myproject/venv/lib/python2.6/site-packages/flask/app.py", line 1475, in full_dispatch_request
    rv = self.dispatch_request()
  File "/usr/local/src/myproject/venv/lib/python2.6/site-packages/flask/app.py", line 1461, in dispatch_request
    return self.view_functions[rule.endpoint](**req.view_args)
  File "/usr/local/src/myproject/myflask/five-six/blog/webapp/controllers/main.py", line 96, in register
    if form.validate_on_submit():
  File "/usr/local/src/myproject/venv/lib/python2.6/site-packages/flask_wtf/form.py", line 166, in validate_on_submit
    return self.is_submitted() and self.validate()
  File "/usr/local/src/myproject/myflask/five-six/blog/webapp/forms.py", line 61, in validate
    check_validate = super(RegisterForm, self).validate()
  File "/usr/local/src/myproject/venv/lib/python2.6/site-packages/wtforms/form.py", line 310, in validate
    return super(Form, self).validate(extra)
  File "/usr/local/src/myproject/venv/lib/python2.6/site-packages/wtforms/form.py", line 152, in validate
    if not field.validate(self, extra):
  File "/usr/local/src/myproject/venv/lib/python2.6/site-packages/wtforms/fields/core.py", line 204, in validate
    stop_validation = self._run_validation_chain(form, chain)
  File "/usr/local/src/myproject/venv/lib/python2.6/site-packages/wtforms/fields/core.py", line 224, in _run_validation_chain
    validator(form, self)
  File "/usr/local/src/myproject/venv/lib/python2.6/site-packages/flask_wtf/recaptcha/validators.py", line 46, in __call__
    if not self._validate_recaptcha(response, remote_ip):
  File "/usr/local/src/myproject/venv/lib/python2.6/site-packages/flask_wtf/recaptcha/validators.py", line 63, in _validate_recaptcha
    http_response = http.urlopen(RECAPTCHA_VERIFY_SERVER, to_bytes(data))
  File "/usr/lib64/python2.6/urllib2.py", line 126, in urlopen
    return _opener.open(url, data, timeout)
  File "/usr/lib64/python2.6/urllib2.py", line 391, in open
    response = self._open(req, data)
  File "/usr/lib64/python2.6/urllib2.py", line 409, in _open
    '_open', req)
  File "/usr/lib64/python2.6/urllib2.py", line 369, in _call_chain
    result = func(*args)
  File "/usr/lib64/python2.6/urllib2.py", line 1198, in https_open
    return self.do_open(httplib.HTTPSConnection, req)
  File "/usr/lib64/python2.6/urllib2.py", line 1165, in do_open
    raise URLError(err)
URLError: <urlopen error [Errno 101] Network is unreachable>
205.252.237.59 - - [25/Mar/2017 09:29:37] "GET /register?__debugger__=yes&cmd=resource&f=style.css HTTP/1.1" 200 -
205.252.237.59 - - [25/Mar/2017 09:29:37] "GET /register?__debugger__=yes&cmd=resource&f=jquery.js HTTP/1.1" 200 -
205.252.237.59 - - [25/Mar/2017 09:29:42] "GET /register?__debugger__=yes&cmd=resource&f=debugger.js HTTP/1.1" 200 -
205.252.237.59 - - [25/Mar/2017 09:29:45] "GET /register?__debugger__=yes&cmd=resource&f=ubuntu.ttf HTTP/1.1" 200 -
205.252.237.59 - - [25/Mar/2017 09:29:46] "GET /register?__debugger__=yes&cmd=resource&f=console.png HTTP/1.1" 200 -
205.252.237.59 - - [25/Mar/2017 09:31:27] "GET / HTTP/1.1" 302 -
205.252.237.59 - - [25/Mar/2017 09:31:27] "GET /blog/ HTTP/1.1" 200 -
205.252.237.59 - - [25/Mar/2017 09:31:32] "GET /register HTTP/1.1" 200 -
205.252.237.59 - - [25/Mar/2017 09:31:34] "GET /facebook HTTP/1.1" 302 -
205.252.237.59 - - [25/Mar/2017 09:33:42] "GET /facebook/authorized?next=http%3A%2F%2Fzbxinstall.kingsoft.com%3A5000%2Fregister&code=AQB-MeJEqzZ1MsHfAlYVZAnqBHDt55Hv3JK1qFXhASQXLaKe0dP27482aMqLgfftEqqO9wBFSP4C7w3EsJElrUARK5-wbgl1zqIyzxuLg9SwhpAVvvZdeZ0RGmaLybkOUVJG9Zh-Bap0hTfpSyCoX343QBpU2bpa6eXYO0cM51U3_BRZeoaae-MDvcfRi5nnLnPLWsg_8do2-dfCJwVXyF3OXZQAaBAN8OOTQ0MfjTUYB_rBvYO7RNONA8czTOm5LbvuMm1cTonebK4arMlvgONwkD9BZVdSilnsw-ksXsQ3FO0F6jUZdRXtq9ttMSXnERRgTMVLCbxcsVDu8hLR3yBc HTTP/1.1" 500 -
Traceback (most recent call last):
  File "/usr/local/src/myproject/venv/lib/python2.6/site-packages/flask/app.py", line 1836, in __call__
    return self.wsgi_app(environ, start_response)
  File "/usr/local/src/myproject/venv/lib/python2.6/site-packages/flask/app.py", line 1820, in wsgi_app
    response = self.make_response(self.handle_exception(e))
  File "/usr/local/src/myproject/venv/lib/python2.6/site-packages/flask/app.py", line 1403, in handle_exception
    reraise(exc_type, exc_value, tb)
  File "/usr/local/src/myproject/venv/lib/python2.6/site-packages/flask/app.py", line 1817, in wsgi_app
    response = self.full_dispatch_request()
  File "/usr/local/src/myproject/venv/lib/python2.6/site-packages/flask/app.py", line 1477, in full_dispatch_request
    rv = self.handle_user_exception(e)
  File "/usr/local/src/myproject/venv/lib/python2.6/site-packages/flask/app.py", line 1381, in handle_user_exception
    reraise(exc_type, exc_value, tb)
  File "/usr/local/src/myproject/venv/lib/python2.6/site-packages/flask/app.py", line 1475, in full_dispatch_request
    rv = self.dispatch_request()
  File "/usr/local/src/myproject/venv/lib/python2.6/site-packages/flask/app.py", line 1461, in dispatch_request
    return self.view_functions[rule.endpoint](**req.view_args)
  File "/usr/local/src/myproject/venv/lib/python2.6/site-packages/flask_oauth.py", line 429, in decorated
    data = self.handle_oauth2_response()
  File "/usr/local/src/myproject/venv/lib/python2.6/site-packages/flask_oauth.py", line 400, in handle_oauth2_response
    resp, content = self._client.request(url, self.access_token_method)
  File "/usr/local/src/myproject/venv/lib/python2.6/site-packages/oauth2/__init__.py", line 687, in request
    connection_type=connection_type)
  File "/usr/local/src/myproject/venv/lib/python2.6/site-packages/httplib2/__init__.py", line 1659, in request
    (response, content) = self._request(conn, authority, uri, request_uri, method, body, headers, redirections, cachekey)
  File "/usr/local/src/myproject/venv/lib/python2.6/site-packages/httplib2/__init__.py", line 1399, in _request
    (response, content) = self._conn_request(conn, request_uri, method, body, headers)
  File "/usr/local/src/myproject/venv/lib/python2.6/site-packages/httplib2/__init__.py", line 1355, in _conn_request
    response = conn.getresponse()
  File "/usr/lib64/python2.6/httplib.py", line 1039, in getresponse
    raise ResponseNotReady()
ResponseNotReady
205.252.237.59 - - [25/Mar/2017 09:33:42] "GET /facebook/authorized?__debugger__=yes&cmd=resource&f=style.css HTTP/1.1" 200 -
205.252.237.59 - - [25/Mar/2017 09:33:42] "GET /facebook/authorized?__debugger__=yes&cmd=resource&f=jquery.js HTTP/1.1" 200 -
205.252.237.59 - - [25/Mar/2017 09:33:45] "GET /facebook/authorized?__debugger__=yes&cmd=resource&f=debugger.js HTTP/1.1" 200 -
205.252.237.59 - - [25/Mar/2017 09:33:46] "GET /facebook/authorized?__debugger__=yes&cmd=resource&f=ubuntu.ttf HTTP/1.1" 200 -
205.252.237.59 - - [25/Mar/2017 09:33:46] "GET /facebook/authorized?__debugger__=yes&cmd=resource&f=console.png HTTP/1.1" 200 -
